<?xml version="1.0" ?>
<!-- Generated using onshape-to-robot -->
<!-- Onshape document_id: 4af8569930bfdc776139afc6 -->
<sdf version="1.7">

<world name="default">
  <model name="mybot">
    <!-- Link base -->
    <link name="base">
      <inertial>
        <pose>-0.0595984 0.133273 0.0193778 0 0 0</pose>
        <mass>0.375499</mass>
        <inertia>
          <ixx>0.00294313</ixx>
          <ixy>0</ixy>
          <ixz>0</ixz>
          <iyy>0.00294313</iyy>
          <iyz>0</iyz>
          <izz>0.00584588</izz>
        </inertia>
      </inertial>
      <pose>0 0 0 0 -0 0</pose>
      <!-- Part base -->
      <visual name="base_visual_mesh_1">
        <pose relative_to="base">-0.0595984 0.133273 0.00667784 0 -0 0</pose>
        <geometry>
          <mesh>
            <uri>model://mybot/assets/base.stl</uri>
          </mesh>
        </geometry>
        <material>
          <ambient>0.615686 0.811765 0.929412 1</ambient>
          <diffuse>0.615686 0.811765 0.929412 1</diffuse>
          <specular>0.1 0.1 0.1 1</specular>
          <emissive>0 0 0 0</emissive>
        </material>
      </visual>
      <collision name="base_collision_mesh_2">
        <pose relative_to="base">-0.0595984 0.133273 0.00667784 0 -0 0</pose>
        <geometry>
          <mesh>
            <uri>model://mybot/assets/base.stl</uri>
          </mesh>
        </geometry>
      </collision>
    </link>
    <joint name="base_fixed_world" type="fixed">
      <parent>world</parent>
      <child>base</child>
    </joint>
    <!-- Link swivle -->
    <link name="swivle">
      <inertial>
        <pose>-0 -0 -0.0232936 0 0 0</pose>
        <mass>0.0630945</mass>
        <inertia>
          <ixx>9.0513e-05</ixx>
          <ixy>-0</ixy>
          <ixz>0</ixz>
          <iyy>0.000101179</iyy>
          <iyz>0</iyz>
          <izz>0.000120893</izz>
        </inertia>
      </inertial>
      <pose relative_to="base_rot">0 0 0 0 -0 0</pose>
      <!-- Part swivle -->
      <visual name="swivle_visual_mesh_1">
        <pose relative_to="swivle">-0 -0 0.0508 3.14159 -0 -0</pose>
        <geometry>
          <mesh>
            <uri>model://mybot/assets/swivle.stl</uri>
          </mesh>
        </geometry>
        <material>
          <ambient>0.647059 0.647059 0.647059 1</ambient>
          <diffuse>0.647059 0.647059 0.647059 1</diffuse>
          <specular>0.1 0.1 0.1 1</specular>
          <emissive>0 0 0 0</emissive>
        </material>
      </visual>
      <collision name="swivle_collision_mesh_2">
        <pose relative_to="swivle">-0 -0 0.0508 3.14159 -0 -0</pose>
        <geometry>
          <mesh>
            <uri>model://mybot/assets/swivle.stl</uri>
          </mesh>
        </geometry>
      </collision>
    </link>
    <!-- Link arm1 -->
    <link name="arm1">
      <inertial>
        <pose>-0.0757655 -0.0589887 -0.0127 0 0 0</pose>
        <mass>0.074836</mass>
        <inertia>
          <ixx>0.000166028</ixx>
          <ixy>-9.36746e-05</ixy>
          <ixz>-1e-12</ixz>
          <iyy>0.000213413</iyy>
          <iyz>-2e-12</iyz>
          <izz>0.000227704</izz>
        </inertia>
      </inertial>
      <pose relative_to="joint1">0 0 0 0 -0 0</pose>
      <!-- Part arm1 -->
      <visual name="arm1_visual_mesh_1">
        <pose relative_to="arm1">0 0.127 -0.0127 1.5708 1.5708 0</pose>
        <geometry>
          <mesh>
            <uri>model://mybot/assets/arm1.stl</uri>
          </mesh>
        </geometry>
        <material>
          <ambient>0.231373 0.380392 0.705882 1</ambient>
          <diffuse>0.231373 0.380392 0.705882 1</diffuse>
          <specular>0.1 0.1 0.1 1</specular>
          <emissive>0 0 0 0</emissive>
        </material>
      </visual>
      <collision name="arm1_collision_mesh_2">
        <pose relative_to="arm1">0 0.127 -0.0127 1.5708 1.5708 0</pose>
        <geometry>
          <mesh>
            <uri>model://mybot/assets/arm1.stl</uri>
          </mesh>
        </geometry>
      </collision>
    </link>
    <!-- Link arm2 -->
    <link name="arm2">
      <inertial>
        <pose>-0.0543508 -0.0377625 -0.0127 0 0 0</pose>
        <mass>0.0341329</mass>
        <inertia>
          <ixx>3.48126e-05</ixx>
          <ixy>-3.61968e-05</ixy>
          <ixz>-0</ixz>
          <iyy>6.17606e-05</iyy>
          <iyz>0</iyz>
          <izz>9.2858e-05</izz>
        </inertia>
      </inertial>
      <pose relative_to="joint2">0 0 0 0 -0 0</pose>
      <!-- Part arm2 -->
      <visual name="arm2_visual_mesh_1">
        <pose relative_to="arm2">0.120251 0.220624 -0.0127 1.5708 1.5708 0</pose>
        <geometry>
          <mesh>
            <uri>model://mybot/assets/arm2.stl</uri>
          </mesh>
        </geometry>
        <material>
          <ambient>0.917647 0.917647 0.917647 1</ambient>
          <diffuse>0.917647 0.917647 0.917647 1</diffuse>
          <specular>0.1 0.1 0.1 1</specular>
          <emissive>0 0 0 0</emissive>
        </material>
      </visual>
      <collision name="arm2_collision_mesh_2">
        <pose relative_to="arm2">0.120251 0.220624 -0.0127 1.5708 1.5708 0</pose>
        <geometry>
          <mesh>
            <uri>model://mybot/assets/arm2.stl</uri>
          </mesh>
        </geometry>
      </collision>
    </link>
    <!-- Link arm1_2 -->
    <link name="arm1_2">
      <inertial>
        <pose>5.93e-10 3.449e-09 -0.146821 0 0 0</pose>
        <mass>0.074836</mass>
        <inertia>
          <ixx>0.000231417</ixx>
          <ixy>1.42814e-05</ixy>
          <ixz>-6e-12</ixz>
          <iyy>0.000282632</iyy>
          <iyz>-2.9e-11</iyz>
          <izz>9.30962e-05</izz>
        </inertia>
      </inertial>
      <pose relative_to="wrist3">0 0 0 0 -0 0</pose>
      <!-- Part arm1_2 -->
      <visual name="arm1_2_visual_mesh_1">
        <pose relative_to="arm1_2">0.0252163 0.0969847 0.0272198 2.23233 -0 -0.254371</pose>
        <geometry>
          <mesh>
            <uri>model://mybot/assets/arm1.stl</uri>
          </mesh>
        </geometry>
        <material>
          <ambient>0.231373 0.380392 0.705882 1</ambient>
          <diffuse>0.231373 0.380392 0.705882 1</diffuse>
          <specular>0.1 0.1 0.1 1</specular>
          <emissive>0 0 0 0</emissive>
        </material>
      </visual>
      <collision name="arm1_2_collision_mesh_2">
        <pose relative_to="arm1_2">0.0252163 0.0969847 0.0272198 2.23233 -0 -0.254371</pose>
        <geometry>
          <mesh>
            <uri>model://mybot/assets/arm1.stl</uri>
          </mesh>
        </geometry>
      </collision>
    </link>
    <!-- Link arm2_2 -->
    <link name="arm2_2">
      <inertial>
        <pose>-0.0543508 -0.0377625 -0.0127 0 0 0</pose>
        <mass>0.0341329</mass>
        <inertia>
          <ixx>3.48126e-05</ixx>
          <ixy>-3.61968e-05</ixy>
          <ixz>0</ixz>
          <iyy>6.17606e-05</iyy>
          <iyz>0</iyz>
          <izz>9.2858e-05</izz>
        </inertia>
      </inertial>
      <pose relative_to="joint4">0 0 0 0 -0 0</pose>
      <!-- Part arm2_2 -->
      <visual name="arm2_2_visual_mesh_1">
        <pose relative_to="arm2_2">0.120251 0.220624 -0.0127 1.5708 1.5708 0</pose>
        <geometry>
          <mesh>
            <uri>model://mybot/assets/arm2.stl</uri>
          </mesh>
        </geometry>
        <material>
          <ambient>0.917647 0.917647 0.917647 1</ambient>
          <diffuse>0.917647 0.917647 0.917647 1</diffuse>
          <specular>0.1 0.1 0.1 1</specular>
          <emissive>0 0 0 0</emissive>
        </material>
      </visual>
      <collision name="arm2_2_collision_mesh_2">
        <pose relative_to="arm2_2">0.120251 0.220624 -0.0127 1.5708 1.5708 0</pose>
        <geometry>
          <mesh>
            <uri>model://mybot/assets/arm2.stl</uri>
          </mesh>
        </geometry>
      </collision>
    </link>
    <!-- Link hand -->
    <link name="hand">
      <inertial>
        <pose>-0 -0 -0.0252044 0 0 0</pose>
        <mass>0.00695227</mass>
        <inertia>
          <ixx>2.44576e-06</ixx>
          <ixy>-0</ixy>
          <ixz>0</ixz>
          <iyy>4.34857e-06</iyy>
          <iyz>-0</iyz>
          <izz>2.67285e-06</izz>
        </inertia>
      </inertial>
      <pose relative_to="wrist5">0 0 0 0 -0 0</pose>
      <!-- Part hand -->
      <visual name="hand_visual_mesh_1">
        <pose relative_to="hand">0.00580608 0.15067 0.407774 2.17802 -0 -0</pose>
        <geometry>
          <mesh>
            <uri>model://mybot/assets/hand.stl</uri>
          </mesh>
        </geometry>
        <material>
          <ambient>0.768627 0.886275 0.952941 1</ambient>
          <diffuse>0.768627 0.886275 0.952941 1</diffuse>
          <specular>0.1 0.1 0.1 1</specular>
          <emissive>0 0 0 0</emissive>
        </material>
      </visual>
      <collision name="hand_collision_mesh_2">
        <pose relative_to="hand">0.00580608 0.15067 0.407774 2.17802 -0 -0</pose>
        <geometry>
          <mesh>
            <uri>model://mybot/assets/hand.stl</uri>
          </mesh>
        </geometry>
      </collision>
    </link>
    <!-- Joint from arm2_2 to hand -->
    <joint name="wrist5" type="revolute">
      <pose relative_to="arm2_2">-0.146016 -0.101451 -0.0127 1.5708 -0.103846 2.17802</pose>
      <parent>arm2_2</parent>
      <child>hand</child>
      <axis>
        <xyz>0 0 1</xyz>
        <limit>
          <effort>10</effort>
          <velocity>10</velocity>
          <lower>-3.141592653589793</lower>
          <upper>3.141592653589793</upper>
        </limit>
        <dynamics>
          <friction>0.0</friction>
          <damping>0.0</damping>
        </dynamics>
      </axis>
    </joint>
    <!-- Joint from arm1_2 to arm2_2 -->
    <joint name="joint4" type="revolute">
      <pose relative_to="arm1_2">-0.0122913 0.00319579 -0.2032 1.5708 1.08193 -1.82517</pose>
      <parent>arm1_2</parent>
      <child>arm2_2</child>
      <axis>
        <xyz>0 0 1</xyz>
        <limit>
          <effort>10</effort>
          <velocity>10</velocity>
          <lower>-3.141592653589793</lower>
          <upper>3.141592653589793</upper>
        </limit>
        <dynamics>
          <friction>0.0</friction>
          <damping>0.0</damping>
        </dynamics>
      </axis>
    </joint>
    <!-- Joint from arm2 to arm1_2 -->
    <joint name="wrist3" type="revolute">
      <pose relative_to="arm2">-0.125156 -0.0869577 -0.0127 -0.607222 1.5708 0</pose>
      <parent>arm2</parent>
      <child>arm1_2</child>
      <axis>
        <xyz>0 0 1</xyz>
        <limit>
          <effort>10</effort>
          <velocity>10</velocity>
          <lower>-3.141592653589793</lower>
          <upper>3.141592653589793</upper>
        </limit>
        <dynamics>
          <friction>0.0</friction>
          <damping>0.0</damping>
        </dynamics>
      </axis>
    </joint>
    <!-- Joint from arm1 to arm2 -->
    <joint name="joint2" type="revolute">
      <pose relative_to="arm1">-0.120251 -0.0936238 -0 0 0 1.71304</pose>
      <parent>arm1</parent>
      <child>arm2</child>
      <axis>
        <xyz>0 0 1</xyz>
        <limit>
          <effort>10</effort>
          <velocity>10</velocity>
          <lower>-3.141592653589793</lower>
          <upper>3.141592653589793</upper>
        </limit>
        <dynamics>
          <friction>0.0</friction>
          <damping>0.0</damping>
        </dynamics>
      </axis>
    </joint>
    <!-- Joint from swivle to arm1 -->
    <joint name="joint1" type="revolute">
      <pose relative_to="swivle">-0.0127 0 -0.0762 1.5708 -0.550725 -1.5708</pose>
      <parent>swivle</parent>
      <child>arm1</child>
      <axis>
        <xyz>0 0 1</xyz>
        <limit>
          <effort>10</effort>
          <velocity>10</velocity>
          <lower>-3.141592653589793</lower>
          <upper>3.141592653589793</upper>
        </limit>
        <dynamics>
          <friction>0.0</friction>
          <damping>0.0</damping>
        </dynamics>
      </axis>
    </joint>
    <!-- Joint from base to swivle -->
    <joint name="base_rot" type="revolute">
      <pose relative_to="base">-0.0595984 0.133273 0.0574778 3.14159 -0 -2.95606</pose>
      <parent>base</parent>
      <child>swivle</child>
      <axis>
        <xyz>0 0 1</xyz>
        <limit>
          <effort>10</effort>
          <velocity>10</velocity>
          <lower>-3.141592653589793</lower>
          <upper>3.141592653589793</upper>
        </limit>
        <dynamics>
          <friction>0.0</friction>
          <damping>0.0</damping>
        </dynamics>
      </axis>
    </joint>



    <plugin filename="gz-sim-joint-position-controller-system" name="gz::sim::systems::JointPositionController">
        <joint_name>base_rot</joint_name>
        <p_gain>100.0</p_gain>
        <i_gain>0.1</i_gain>
        <d_gain>0.01</d_gain>
    </plugin>
    <plugin filename="gz-sim-joint-position-controller-system" name="gz::sim::systems::JointPositionController">
        <joint_name>joint1</joint_name>
        <p_gain>100.0</p_gain>
        <i_gain>0.1</i_gain>
        <d_gain>0.01</d_gain>
    </plugin>
    <plugin filename="gz-sim-joint-position-controller-system" name="gz::sim::systems::JointPositionController">
        <joint_name>joint2</joint_name>
        <p_gain>100.0</p_gain>
        <i_gain>0.1</i_gain>
        <d_gain>0.01</d_gain>
    </plugin>
    <plugin filename="gz-sim-joint-position-controller-system" name="gz::sim::systems::JointPositionController">
        <joint_name>wrist3</joint_name>
        <p_gain>100.0</p_gain>
        <i_gain>0.1</i_gain>
        <d_gain>0.01</d_gain>
    </plugin>
    <plugin filename="gz-sim-joint-position-controller-system" name="gz::sim::systems::JointPositionController">
        <joint_name>joint4</joint_name>
        <p_gain>100.0</p_gain>
        <i_gain>0.1</i_gain>
        <d_gain>0.01</d_gain>
    </plugin>
    <plugin filename="gz-sim-joint-position-controller-system" name="gz::sim::systems::JointPositionController">
        <joint_name>wrist5</joint_name>
        <p_gain>100.0</p_gain>
        <i_gain>0.1</i_gain>
        <d_gain>0.01</d_gain>
    </plugin>











  </model>

  <model name="target_sphere">
    <pose>0.5 0.0 1.0 0 0 0</pose> <link name="sphere_link">
      <kinematic>true</kinematic> 
      <gravity>false</gravity>    
      
      <visual name="visual">
        <geometry>
          <sphere><radius>0.05</radius></sphere>
        </geometry>
        <material>
          <ambient>1 0 0 1</ambient> 
          <diffuse>1 0 0 1</diffuse>
        </material>
      </visual>
      

    </link>

    <plugin filename="gz-sim-pose-publisher-system" name="gz::sim::systems::PosePublisher">
      <publish_link_pose>false</publish_link_pose>
      <publish_model_pose>true</publish_model_pose>
      <update_frequency>20</update_frequency> 
    </plugin>
  </model>



</world>

</sdf>
