<?xml version="1.0" ?>
<!-- Generated using onshape-to-robot -->
<!-- Onshape document_id: 4af8569930bfdc776139afc6 -->
<robot name="mybot">
  <!-- Link base -->
  <link name="base">
    <inertial>
      <origin xyz="-0.0595984 0.133273 0.0193778" rpy="0 0 0"/>
      <mass value="0.375499"/>
      <inertia ixx="0.00294313" ixy="0" ixz="0" iyy="0.00294313" iyz="0" izz="0.00584588"/>
    </inertial>
    <!-- Part base -->
    <visual>
      <origin xyz="-0.0595984 0.133273 0.00667784" rpy="0 -0 0"/>
      <geometry>
        <mesh filename="package://assets/base.stl"/>
      </geometry>
      <material name="base_material">
        <color rgba="0.615686 0.811765 0.929412 1"/>
      </material>
    </visual>
    <collision>
      <origin xyz="-0.0595984 0.133273 0.00667784" rpy="0 -0 0"/>
      <geometry>
        <mesh filename="package://assets/base.stl"/>
      </geometry>
    </collision>
  </link>
  <!-- Link swivle -->
  <link name="swivle">
    <inertial>
      <origin xyz="-0 -0 -0.0232936" rpy="0 0 0"/>
      <mass value="0.0630945"/>
      <inertia ixx="9.0513e-05" ixy="-0" ixz="0" iyy="0.000101179" iyz="0" izz="0.000120893"/>
    </inertial>
    <!-- Part swivle -->
    <visual>
      <origin xyz="-0 -0 0.0508" rpy="3.14159 -0 -0"/>
      <geometry>
        <mesh filename="package://assets/swivle.stl"/>
      </geometry>
      <material name="swivle_material">
        <color rgba="0.647059 0.647059 0.647059 1"/>
      </material>
    </visual>
    <collision>
      <origin xyz="-0 -0 0.0508" rpy="3.14159 -0 -0"/>
      <geometry>
        <mesh filename="package://assets/swivle.stl"/>
      </geometry>
    </collision>
  </link>
  <!-- Link arm1 -->
  <link name="arm1">
    <inertial>
      <origin xyz="-0.0757655 -0.0589887 -0.0127" rpy="0 0 0"/>
      <mass value="0.074836"/>
      <inertia ixx="0.000166028" ixy="-9.36746e-05" ixz="-1e-12" iyy="0.000213413" iyz="-2e-12" izz="0.000227704"/>
    </inertial>
    <!-- Part arm1 -->
    <visual>
      <origin xyz="0 0.127 -0.0127" rpy="1.5708 1.5708 0"/>
      <geometry>
        <mesh filename="package://assets/arm1.stl"/>
      </geometry>
      <material name="arm1_material">
        <color rgba="0.231373 0.380392 0.705882 1"/>
      </material>
    </visual>
    <collision>
      <origin xyz="0 0.127 -0.0127" rpy="1.5708 1.5708 0"/>
      <geometry>
        <mesh filename="package://assets/arm1.stl"/>
      </geometry>
    </collision>
  </link>
  <!-- Link arm2 -->
  <link name="arm2">
    <inertial>
      <origin xyz="-0.0543508 -0.0377625 -0.0127" rpy="0 0 0"/>
      <mass value="0.0341329"/>
      <inertia ixx="3.48126e-05" ixy="-3.61968e-05" ixz="-0" iyy="6.17606e-05" iyz="0" izz="9.2858e-05"/>
    </inertial>
    <!-- Part arm2 -->
    <visual>
      <origin xyz="0.120251 0.220624 -0.0127" rpy="1.5708 1.5708 0"/>
      <geometry>
        <mesh filename="package://assets/arm2.stl"/>
      </geometry>
      <material name="arm2_material">
        <color rgba="0.917647 0.917647 0.917647 1"/>
      </material>
    </visual>
    <collision>
      <origin xyz="0.120251 0.220624 -0.0127" rpy="1.5708 1.5708 0"/>
      <geometry>
        <mesh filename="package://assets/arm2.stl"/>
      </geometry>
    </collision>
  </link>
  <!-- Link arm1_2 -->
  <link name="arm1_2">
    <inertial>
      <origin xyz="5.93e-10 3.449e-09 -0.146821" rpy="0 0 0"/>
      <mass value="0.074836"/>
      <inertia ixx="0.000231417" ixy="1.42814e-05" ixz="-6e-12" iyy="0.000282632" iyz="-2.9e-11" izz="9.30962e-05"/>
    </inertial>
    <!-- Part arm1_2 -->
    <visual>
      <origin xyz="0.0252163 0.0969847 0.0272198" rpy="2.23233 -0 -0.254371"/>
      <geometry>
        <mesh filename="package://assets/arm1.stl"/>
      </geometry>
      <material name="arm1_2_material">
        <color rgba="0.231373 0.380392 0.705882 1"/>
      </material>
    </visual>
    <collision>
      <origin xyz="0.0252163 0.0969847 0.0272198" rpy="2.23233 -0 -0.254371"/>
      <geometry>
        <mesh filename="package://assets/arm1.stl"/>
      </geometry>
    </collision>
  </link>
  <!-- Link arm2_2 -->
  <link name="arm2_2">
    <inertial>
      <origin xyz="-0.0543508 -0.0377625 -0.0127" rpy="0 0 0"/>
      <mass value="0.0341329"/>
      <inertia ixx="3.48126e-05" ixy="-3.61968e-05" ixz="0" iyy="6.17606e-05" iyz="0" izz="9.2858e-05"/>
    </inertial>
    <!-- Part arm2_2 -->
    <visual>
      <origin xyz="0.120251 0.220624 -0.0127" rpy="1.5708 1.5708 0"/>
      <geometry>
        <mesh filename="package://assets/arm2.stl"/>
      </geometry>
      <material name="arm2_2_material">
        <color rgba="0.917647 0.917647 0.917647 1"/>
      </material>
    </visual>
    <collision>
      <origin xyz="0.120251 0.220624 -0.0127" rpy="1.5708 1.5708 0"/>
      <geometry>
        <mesh filename="package://assets/arm2.stl"/>
      </geometry>
    </collision>
  </link>
  <!-- Link hand -->
  <link name="hand">
    <inertial>
      <origin xyz="-0 -0 -0.0252044" rpy="0 0 0"/>
      <mass value="0.00695227"/>
      <inertia ixx="2.44576e-06" ixy="-0" ixz="0" iyy="4.34857e-06" iyz="-0" izz="2.67285e-06"/>
    </inertial>
    <!-- Part hand -->
    <visual>
      <origin xyz="0.00580608 0.15067 0.407774" rpy="2.17802 -0 -0"/>
      <geometry>
        <mesh filename="package://assets/hand.stl"/>
      </geometry>
      <material name="hand_material">
        <color rgba="0.768627 0.886275 0.952941 1"/>
      </material>
    </visual>
    <collision>
      <origin xyz="0.00580608 0.15067 0.407774" rpy="2.17802 -0 -0"/>
      <geometry>
        <mesh filename="package://assets/hand.stl"/>
      </geometry>
    </collision>
  </link>
  <!-- Joint from arm2_2 to hand -->
  <joint name="wrist5" type="revolute">
    <origin xyz="-0.146016 -0.101451 -0.0127" rpy="1.5708 -0.103846 2.17802"/>
    <parent link="arm2_2"/>
    <child link="hand"/>
    <axis xyz="0 0 1"/>
    <limit effort="10" velocity="10" lower="-3.141592653589793" upper="3.141592653589793"/>
  </joint>
  <!-- Joint from arm1_2 to arm2_2 -->
  <joint name="joint4" type="revolute">
    <origin xyz="-0.0122913 0.00319579 -0.2032" rpy="1.5708 1.08193 -1.82517"/>
    <parent link="arm1_2"/>
    <child link="arm2_2"/>
    <axis xyz="0 0 1"/>
    <limit effort="10" velocity="10" lower="-3.141592653589793" upper="3.141592653589793"/>
  </joint>
  <!-- Joint from arm2 to arm1_2 -->
  <joint name="wrist3" type="revolute">
    <origin xyz="-0.125156 -0.0869577 -0.0127" rpy="-0.607222 1.5708 0"/>
    <parent link="arm2"/>
    <child link="arm1_2"/>
    <axis xyz="0 0 1"/>
    <limit effort="10" velocity="10" lower="-3.141592653589793" upper="3.141592653589793"/>
  </joint>
  <!-- Joint from arm1 to arm2 -->
  <joint name="joint2" type="revolute">
    <origin xyz="-0.120251 -0.0936238 -0" rpy="0 0 1.71304"/>
    <parent link="arm1"/>
    <child link="arm2"/>
    <axis xyz="0 0 1"/>
    <limit effort="10" velocity="10" lower="-3.141592653589793" upper="3.141592653589793"/>
  </joint>
  <!-- Joint from swivle to arm1 -->
  <joint name="joint1" type="revolute">
    <origin xyz="-0.0127 0 -0.0762" rpy="1.5708 -0.550725 -1.5708"/>
    <parent link="swivle"/>
    <child link="arm1"/>
    <axis xyz="0 0 1"/>
    <limit effort="10" velocity="10" lower="-3.141592653589793" upper="3.141592653589793"/>
  </joint>
  <!-- Joint from base to swivle -->
  <joint name="base_rot" type="revolute">
    <origin xyz="-0.0595984 0.133273 0.0574778" rpy="3.14159 -0 -2.95606"/>
    <parent link="base"/>
    <child link="swivle"/>
    <axis xyz="0 0 1"/>
    <limit effort="10" velocity="10" lower="-3.141592653589793" upper="3.141592653589793"/>
  </joint>
</robot>
